<?xml version="1.0"?>

<robot name="robot1">
  <link name="base_link"/>

  <joint name="body_joint" type="fixed">
    <parent link="base_link"/>
    <child  link="body_link"/>
    <origin xyz="0.5 0 0" rpy="0 0 0"/>
  </joint>
  <link name="body_link">
    <visual>
      <geometry>
        <box size="0.3 0.3 0.2"/>
      </geometry>
      <origin xyz="0 0 0" rpy="0 0 0"/>
      <material name="red">
        <color rgba="1.0 0.0 0.0 2.0"/>
      </material>
    </visual>
  </link>

  <joint name="elevator_joint" type="prismatic">
    <axis xyz="1 0 0"/>
    <origin xyz="0.0 0.0 0.0"/>
    <parent link="base_link"/>
    <child link="elevator"/>
    <limit effort="1000.0" lower="-15" upper="15" velocity="30"/>
    <dynamics damping="0.0" friction="0.0"/>
  </joint>
  <link name="elevator">
    <visual>
      <geometry>
        <box size="0.1 0.1 0.1"/>
      </geometry>
      <origin xyz="0 0 0"/>
      <material name="blue">
        <color rgba="0 0 .8 1"/>
      </material>
    </visual>
    <inertial>
      <mass value="1"/>
      <inertia ixx="1.0" ixy="0.0" ixz="0.0" iyy="1.0" iyz="0.0" izz="1.0"/>
    </inertial>
  </link>
</robot>